[2025-04-06 00:25:32,897] {taskinstance.py:670} INFO - Dependencies all met for <TaskInstance: PythonOperator_DAG.Get_Name 2025-04-04T00:00:00+00:00 [queued]>
[2025-04-06 00:25:32,914] {taskinstance.py:670} INFO - Dependencies all met for <TaskInstance: PythonOperator_DAG.Get_Name 2025-04-04T00:00:00+00:00 [queued]>
[2025-04-06 00:25:32,914] {taskinstance.py:880} INFO - 
--------------------------------------------------------------------------------
[2025-04-06 00:25:32,914] {taskinstance.py:881} INFO - Starting attempt 2 of 2
[2025-04-06 00:25:32,914] {taskinstance.py:882} INFO - 
--------------------------------------------------------------------------------
[2025-04-06 00:25:32,921] {taskinstance.py:901} INFO - Executing <Task(PythonOperator): Get_Name> on 2025-04-04T00:00:00+00:00
[2025-04-06 00:25:32,923] {standard_task_runner.py:54} INFO - Started process 131631 to run task
[2025-04-06 00:25:32,950] {standard_task_runner.py:77} INFO - Running: ['airflow', 'run', 'PythonOperator_DAG', 'Get_Name', '2025-04-04T00:00:00+00:00', '--job_id', '60', '--pool', 'default_pool', '--raw', '-sd', 'DAGS_FOLDER/py_dag.py', '--cfg_path', '/tmp/tmp02s5nj4h']
[2025-04-06 00:25:32,951] {standard_task_runner.py:78} INFO - Job 60: Subtask Get_Name
[2025-04-06 00:25:32,983] {logging_mixin.py:120} INFO - Running <TaskInstance: PythonOperator_DAG.Get_Name 2025-04-04T00:00:00+00:00 [running]> on host ROGZephyrusG14GA401QHGA401QH2abf6ae9
[2025-04-06 00:25:33,004] {taskinstance.py:1150} ERROR - init_name() got an unexpected keyword argument 'conf'
Traceback (most recent call last):
  File "/home/parveensharma/Documents/PythonPractice/Airflow_ETL/airflow_etl_venv/lib/python3.8/site-packages/airflow/models/taskinstance.py", line 984, in _run_raw_task
    result = task_copy.execute(context=context)
  File "/home/parveensharma/Documents/PythonPractice/Airflow_ETL/airflow_etl_venv/lib/python3.8/site-packages/airflow/operators/python_operator.py", line 113, in execute
    return_value = self.execute_callable()
  File "/home/parveensharma/Documents/PythonPractice/Airflow_ETL/airflow_etl_venv/lib/python3.8/site-packages/airflow/operators/python_operator.py", line 118, in execute_callable
    return self.python_callable(*self.op_args, **self.op_kwargs)
TypeError: init_name() got an unexpected keyword argument 'conf'
[2025-04-06 00:25:33,005] {taskinstance.py:1187} INFO - Marking task as FAILED. dag_id=PythonOperator_DAG, task_id=Get_Name, execution_date=20250404T000000, start_date=20250405T185532, end_date=20250405T185533
[2025-04-06 00:25:37,907] {local_task_job.py:102} INFO - Task exited with return code 1
