[2025-04-06 00:27:00,263] {taskinstance.py:670} INFO - Dependencies all met for <TaskInstance: PythonOperator_DAG.Get_Name 2025-04-04T00:00:00+00:00 [queued]>
[2025-04-06 00:27:00,281] {taskinstance.py:670} INFO - Dependencies all met for <TaskInstance: PythonOperator_DAG.Get_Name 2025-04-04T00:00:00+00:00 [queued]>
[2025-04-06 00:27:00,281] {taskinstance.py:880} INFO - 
--------------------------------------------------------------------------------
[2025-04-06 00:27:00,281] {taskinstance.py:881} INFO - Starting attempt 3 of 3
[2025-04-06 00:27:00,281] {taskinstance.py:882} INFO - 
--------------------------------------------------------------------------------
[2025-04-06 00:27:00,286] {taskinstance.py:901} INFO - Executing <Task(PythonOperator): Get_Name> on 2025-04-04T00:00:00+00:00
[2025-04-06 00:27:00,288] {standard_task_runner.py:54} INFO - Started process 132361 to run task
[2025-04-06 00:27:00,317] {standard_task_runner.py:77} INFO - Running: ['airflow', 'run', 'PythonOperator_DAG', 'Get_Name', '2025-04-04T00:00:00+00:00', '--job_id', '62', '--pool', 'default_pool', '--raw', '-sd', 'DAGS_FOLDER/py_dag.py', '--cfg_path', '/tmp/tmpjxrakjy2']
[2025-04-06 00:27:00,317] {standard_task_runner.py:78} INFO - Job 62: Subtask Get_Name
[2025-04-06 00:27:00,347] {logging_mixin.py:120} INFO - Running <TaskInstance: PythonOperator_DAG.Get_Name 2025-04-04T00:00:00+00:00 [running]> on host ROGZephyrusG14GA401QHGA401QH2abf6ae9
[2025-04-06 00:27:00,365] {taskinstance.py:1150} ERROR - init_name() got an unexpected keyword argument 'conf'
Traceback (most recent call last):
  File "/home/parveensharma/Documents/PythonPractice/Airflow_ETL/airflow_etl_venv/lib/python3.8/site-packages/airflow/models/taskinstance.py", line 984, in _run_raw_task
    result = task_copy.execute(context=context)
  File "/home/parveensharma/Documents/PythonPractice/Airflow_ETL/airflow_etl_venv/lib/python3.8/site-packages/airflow/operators/python_operator.py", line 113, in execute
    return_value = self.execute_callable()
  File "/home/parveensharma/Documents/PythonPractice/Airflow_ETL/airflow_etl_venv/lib/python3.8/site-packages/airflow/operators/python_operator.py", line 118, in execute_callable
    return self.python_callable(*self.op_args, **self.op_kwargs)
TypeError: init_name() got an unexpected keyword argument 'conf'
[2025-04-06 00:27:00,365] {taskinstance.py:1187} INFO - Marking task as FAILED. dag_id=PythonOperator_DAG, task_id=Get_Name, execution_date=20250404T000000, start_date=20250405T185700, end_date=20250405T185700
[2025-04-06 00:27:05,252] {local_task_job.py:102} INFO - Task exited with return code 1
